Workbook

Sheet Input
B1: =IF(A1="", "", IF(OR(A1="BLANK", A1="MEMO"), "", 1)) | E1: Vehicle
B2: =IF(A2="", "", IF(OR(A2="BLANK", A2="MEMO"), "", 1)) | E2: Model
B3: =IF(A3="", "", IF(OR(A3="BLANK", A3="MEMO"), "", 1)) | E3: Language
B4: =IF(A4="", "", IF(OR(A4="BLANK", A4="MEMO"), "", 1)) | E4: Pub. Number
B5: =IF(A5="", "", IF(OR(A5="BLANK", A5="MEMO"), "", 1)) | E5: Date
B6: =IF(A6="", "", IF(OR(A6="BLANK", A6="MEMO"), "", 1)) | E6: Quantity
B7: =IF(A7="", "", IF(OR(A7="BLANK", A7="MEMO"), "", 1)) | E7: Revised version
B8: =IF(A8="", "", IF(OR(A8="BLANK", A8="MEMO"), "", 1)) | E8: Full page | F8: =COUNTA(A:A) -> 0
B9: =IF(A9="", "", IF(OR(A9="BLANK", A9="MEMO"), "", 1)) | E9: Change page | F9: =COUNTIF(B:B,1) -> 0
B10: =IF(A10="", "", IF(OR(A10="BLANK", A10="MEMO"), "", 1)) | E10: barcode
B11: =IF(A11="", "", IF(OR(A11="BLANK", A11="MEMO"), "", 1)) | E11: Translation line | F11: -
B12: =IF(A12="", "", IF(OR(A12="BLANK", A12="MEMO"), "", 1))
B13: =IF(A13="", "", IF(OR(A13="BLANK", A13="MEMO"), "", 1))
B14: =IF(A14="", "", IF(OR(A14="BLANK", A14="MEMO"), "", 1))
B15: =IF(A15="", "", IF(OR(A15="BLANK", A15="MEMO"), "", 1))
B16: =IF(A16="", "", IF(OR(A16="BLANK", A16="MEMO"), "", 1))
B17: =IF(A17="", "", IF(OR(A17="BLANK", A17="MEMO"), "", 1))
B18: =IF(A18="", "", IF(OR(A18="BLANK", A18="MEMO"), "", 1))
B19: =IF(A19="", "", IF(OR(A19="BLANK", A19="MEMO"), "", 1))
B20: =IF(A20="", "", IF(OR(A20="BLANK", A20="MEMO"), "", 1))
B21: =IF(A21="", "", IF(OR(A21="BLANK", A21="MEMO"), "", 1))
B22: =IF(A22="", "", IF(OR(A22="BLANK", A22="MEMO"), "", 1))
B23: =IF(A23="", "", IF(OR(A23="BLANK", A23="MEMO"), "", 1))
... B1500: =IF(A1500="", "", IF(OR(A1500="BLANK", A1500="MEMO"), "", 1))

Sheet 차명_언어_연식
A1: Table Array | AG1: Unhide when page grows ≫
A3: =Input!E1 -> Vehicle | D3: =Input!F1 -> 0 | G3: =Input!E7 -> Revised version | J3: =Input!F7 -> 0
A4: =Input!E2 -> Model | D4: =Input!F2 -> 0 | G4: =Input!E8 -> Full page | J4: =Input!F8 -> 0
A5: =Input!E3 -> Language | D5: =Input!F3 -> 0 | G5: =Input!E9 -> Change page | J5: =Input!F9 -> 0
A6: =Input!E4 -> Pub. Number | D6: =Input!F4 -> 0 | G6: =Input!E10 -> barcode | J6: =Input!F10 -> 0
A7: =Input!E5 -> Date | D7: =Input!F5 -> 0 | G7: =Input!E11 -> Translation line | J7: =Input!F11 -> -
A8: =Input!E6 -> Quantity | D8: =Input!F6 -> 0
B10: P | C10: C | E10: P | F10: C | H10: P | I10: C | K10: P | L10: C | N10: P | O10: C | Q10: P | R10: C | T10: P | U10: C | W10: P | X10: C | Z10: P | AA10: C | AC10: P | AD10: C | AF10: P | AG10: C | AI10: P | AJ10: C | AL10: P | AM10: C | AO10: P | AP10: C | AR10: P | AS10: C | AU10: P | AV10: C | AX10: P | AY10: C
A11: 1 | B11: 1 | C11: =Input!A1 -> 0 | D11: 9 | E11: 65 | F11: =Input!A65 -> 0 | G11: 17 | H11: 129 | I11: =Input!A129 -> 0 | J11: 25 | K11: 193 | L11: =Input!A193 -> 0 | M11: 33 | N11: 257 | O11: =Input!A257 -> 0 | P11: 41 | Q11: 321 | R11: =Input!A321 -> 0 | S11: 49 | T11: 385 | U11: =Input!A385 -> 0 | V11: 57 | W11: 449 | X11: =Input!A449 -> 0 | Y11: 65 | Z11: 513 | AA11: =Input!A513 -> 0 | AB11: 73 | AC11: 577 | AD11: =Input!A577 -> 0 | AE11: 81 | AF11: 641 | AG11: =Input!A641 -> 0 | AH11: 89 | AI11: 705 | AJ11: =Input!A705 -> 0 | AK11: 97 | AL11: 769 | AM11: =Input!A769 -> 0 | AN11: 105 | AO11: 833 | AP11: =Input!A833 -> 0 | AQ11: 113 | AR11: 897 | AS11: =Input!A897 -> 0 | AT11: 121 | AU11: 961 | AV11: =Input!A961 -> 0 | AW11: 129 | AX11: 1025 | AY11: =Input!A1025 -> 0
B12: 2 | C12: =Input!A2 -> 0 | E12: 66 | F12: =Input!A66 -> 0 | H12: 130 | I12: =Input!A130 -> 0 | K12: 194 | L12: =Input!A194 -> 0 | N12: 258 | O12: =Input!A258 -> 0 | Q12: 322 | R12: =Input!A322 -> 0 | T12: 386 | U12: =Input!A386 -> 0 | W12: 450 | X12: =Input!A450 -> 0 | Z12: 514 | AA12: =Input!A514 -> 0 | AC12: 578 | AD12: =Input!A578 -> 0 | AF12: 642 | AG12: =Input!A642 -> 0 | AI12: 706 | AJ12: =Input!A706 -> 0 | AL12: 770 | AM12: =Input!A770 -> 0 | AO12: 834 | AP12: =Input!A834 -> 0 | AR12: 898 | AS12: =Input!A898 -> 0 | AU12: 962 | AV12: =Input!A962 -> 0 | AX12: 1026 | AY12: =Input!A1026 -> 0
B13: 3 | C13: =Input!A3 -> 0 | E13: 67 | F13: =Input!A67 -> 0 | H13: 131 | I13: =Input!A131 -> 0 | K13: 195 | L13: =Input!A195 -> 0 | N13: 259 | O13: =Input!A259 -> 0 | Q13: 323 | R13: =Input!A323 -> 0 | T13: 387 | U13: =Input!A387 -> 0 | W13: 451 | X13: =Input!A451 -> 0 | Z13: 515 | AA13: =Input!A515 -> 0 | AC13: 579 | AD13: =Input!A579 -> 0 | AF13: 643 | AG13: =Input!A643 -> 0 | AI13: 707 | AJ13: =Input!A707 -> 0 | AL13: 771 | AM13: =Input!A771 -> 0 | AO13: 835 | AP13: =Input!A835 -> 0 | AR13: 899 | AS13: =Input!A899 -> 0 | AU13: 963 | AV13: =Input!A963 -> 0 | AX13: 1027 | AY13: =Input!A1027 -> 0
B14: 4 | C14: =Input!A4 -> 0 | E14: 68 | F14: =Input!A68 -> 0 | H14: 132 | I14: =Input!A132 -> 0 | K14: 196 | L14: =Input!A196 -> 0 | N14: 260 | O14: =Input!A260 -> 0 | Q14: 324 | R14: =Input!A324 -> 0 | T14: 388 | U14: =Input!A388 -> 0 | W14: 452 | X14: =Input!A452 -> 0 | Z14: 516 | AA14: =Input!A516 -> 0 | AC14: 580 | AD14: =Input!A580 -> 0 | AF14: 644 | AG14: =Input!A644 -> 0 | AI14: 708 | AJ14: =Input!A708 -> 0 | AL14: 772 | AM14: =Input!A772 -> 0 | AO14: 836 | AP14: =Input!A836 -> 0 | AR14: 900 | AS14: =Input!A900 -> 0 | AU14: 964 | AV14: =Input!A964 -> 0 | AX14: 1028 | AY14: =Input!A1028 -> 0
B15: 5 | C15: =Input!A5 -> 0 | E15: 69 | F15: =Input!A69 -> 0 | H15: 133 | I15: =Input!A133 -> 0 | K15: 197 | L15: =Input!A197 -> 0 | N15: 261 | O15: =Input!A261 -> 0 | Q15: 325 | R15: =Input!A325 -> 0 | T15: 389 | U15: =Input!A389 -> 0 | W15: 453 | X15: =Input!A453 -> 0 | Z15: 517 | AA15: =Input!A517 -> 0 | AC15: 581 | AD15: =Input!A581 -> 0 | AF15: 645 | AG15: =Input!A645 -> 0 | AI15: 709 | AJ15: =Input!A709 -> 0 | AL15: 773 | AM15: =Input!A773 -> 0 | AO15: 837 | AP15: =Input!A837 -> 0 | AR15: 901 | AS15: =Input!A901 -> 0 | AU15: 965 | AV15: =Input!A965 -> 0 | AX15: 1029 | AY15: =Input!A1029 -> 0
B16: 6 | C16: =Input!A6 -> 0 | E16: 70 | F16: =Input!A70 -> 0 | H16: 134 | I16: =Input!A134 -> 0 | K16: 198 | L16: =Input!A198 -> 0 | N16: 262 | O16: =Input!A262 -> 0 | Q16: 326 | R16: =Input!A326 -> 0 | T16: 390 | U16: =Input!A390 -> 0 | W16: 454 | X16: =Input!A454 -> 0 | Z16: 518 | AA16: =Input!A518 -> 0 | AC16: 582 | AD16: =Input!A582 -> 0 | AF16: 646 | AG16: =Input!A646 -> 0 | AI16: 710 | AJ16: =Input!A710 -> 0 | AL16: 774 | AM16: =Input!A774 -> 0 | AO16: 838 | AP16: =Input!A838 -> 0 | AR16: 902 | AS16: =Input!A902 -> 0 | AU16: 966 | AV16: =Input!A966 -> 0 | AX16: 1030 | AY16: =Input!A1030 -> 0
B17: 7 | C17: =Input!A7 -> 0 | E17: 71 | F17: =Input!A71 -> 0 | H17: 135 | I17: =Input!A135 -> 0 | K17: 199 | L17: =Input!A199 -> 0 | N17: 263 | O17: =Input!A263 -> 0 | Q17: 327 | R17: =Input!A327 -> 0 | T17: 391 | U17: =Input!A391 -> 0 | W17: 455 | X17: =Input!A455 -> 0 | Z17: 519 | AA17: =Input!A519 -> 0 | AC17: 583 | AD17: =Input!A583 -> 0 | AF17: 647 | AG17: =Input!A647 -> 0 | AI17: 711 | AJ17: =Input!A711 -> 0 | AL17: 775 | AM17: =Input!A775 -> 0 | AO17: 839 | AP17: =Input!A839 -> 0 | AR17: 903 | AS17: =Input!A903 -> 0 | AU17: 967 | AV17: =Input!A967 -> 0 | AX17: 1031 | AY17: =Input!A1031 -> 0
B18: 8 | C18: =Input!A8 -> 0 | E18: 72 | F18: =Input!A72 -> 0 | H18: 136 | I18: =Input!A136 -> 0 | K18: 200 | L18: =Input!A200 -> 0 | N18: 264 | O18: =Input!A264 -> 0 | Q18: 328 | R18: =Input!A328 -> 0 | T18: 392 | U18: =Input!A392 -> 0 | W18: 456 | X18: =Input!A456 -> 0 | Z18: 520 | AA18: =Input!A520 -> 0 | AC18: 584 | AD18: =Input!A584 -> 0 | AF18: 648 | AG18: =Input!A648 -> 0 | AI18: 712 | AJ18: =Input!A712 -> 0 | AL18: 776 | AM18: =Input!A776 -> 0 | AO18: 840 | AP18: =Input!A840 -> 0 | AR18: 904 | AS18: =Input!A904 -> 0 | AU18: 968 | AV18: =Input!A968 -> 0 | AX18: 1032 | AY18: =Input!A1032 -> 0
A19: 2 | B19: 9 | C19: =Input!A9 -> 0 | D19: 10 | E19: 73 | F19: =Input!A73 -> 0 | G19: 18 | H19: 137 | I19: =Input!A137 -> 0 | J19: 26 | K19: 201 | L19: =Input!A201 -> 0 | M19: 34 | N19: 265 | O19: =Input!A265 -> 0 | P19: 42 | Q19: 329 | R19: =Input!A329 -> 0 | S19: 50 | T19: 393 | U19: =Input!A393 -> 0 | V19: 58 | W19: 457 | X19: =Input!A457 -> 0 | Y19: 66 | Z19: 521 | AA19: =Input!A521 -> 0 | AB19: 74 | AC19: 585 | AD19: =Input!A585 -> 0 | AE19: 82 | AF19: 649 | AG19: =Input!A649 -> 0 | AH19: 90 | AI19: 713 | AJ19: =Input!A713 -> 0 | AK19: 98 | AL19: 777 | AM19: =Input!A777 -> 0 | AN19: 106 | AO19: 841 | AP19: =Input!A841 -> 0 | AQ19: 114 | AR19: 905 | AS19: =Input!A905 -> 0 | AT19: 122 | AU19: 969 | AV19: =Input!A969 -> 0 | AW19: 130 | AX19: 1033 | AY19: =Input!A1033 -> 0
B20: 10 | C20: =Input!A10 -> 0 | E20: 74 | F20: =Input!A74 -> 0 | H20: 138 | I20: =Input!A138 -> 0 | K20: 202 | L20: =Input!A202 -> 0 | N20: 266 | O20: =Input!A266 -> 0 | Q20: 330 | R20: =Input!A330 -> 0 | T20: 394 | U20: =Input!A394 -> 0 | W20: 458 | X20: =Input!A458 -> 0 | Z20: 522 | AA20: =Input!A522 -> 0 | AC20: 586 | AD20: =Input!A586 -> 0 | AF20: 650 | AG20: =Input!A650 -> 0 | AI20: 714 | AJ20: =Input!A714 -> 0 | AL20: 778 | AM20: =Input!A778 -> 0 | AO20: 842 | AP20: =Input!A842 -> 0 | AR20: 906 | AS20: =Input!A906 -> 0 | AU20: 970 | AV20: =Input!A970 -> 0 | AX20: 1034 | AY20: =Input!A1034 -> 0
B21: 11 | C21: =Input!A11 -> 0 | E21: 75 | F21: =Input!A75 -> 0 | H21: 139 | I21: =Input!A139 -> 0 | K21: 203 | L21: =Input!A203 -> 0 | N21: 267 | O21: =Input!A267 -> 0 | Q21: 331 | R21: =Input!A331 -> 0 | T21: 395 | U21: =Input!A395 -> 0 | W21: 459 | X21: =Input!A459 -> 0 | Z21: 523 | AA21: =Input!A523 -> 0 | AC21: 587 | AD21: =Input!A587 -> 0 | AF21: 651 | AG21: =Input!A651 -> 0 | AI21: 715 | AJ21: =Input!A715 -> 0 | AL21: 779 | AM21: =Input!A779 -> 0 | AO21: 843 | AP21: =Input!A843 -> 0 | AR21: 907 | AS21: =Input!A907 -> 0 | AU21: 971 | AV21: =Input!A971 -> 0 | AX21: 1035 | AY21: =Input!A1035 -> 0
B22: 12 | C22: =Input!A12 -> 0 | E22: 76 | F22: =Input!A76 -> 0 | H22: 140 | I22: =Input!A140 -> 0 | K22: 204 | L22: =Input!A204 -> 0 | N22: 268 | O22: =Input!A268 -> 0 | Q22: 332 | R22: =Input!A332 -> 0 | T22: 396 | U22: =Input!A396 -> 0 | W22: 460 | X22: =Input!A460 -> 0 | Z22: 524 | AA22: =Input!A524 -> 0 | AC22: 588 | AD22: =Input!A588 -> 0 | AF22: 652 | AG22: =Input!A652 -> 0 | AI22: 716 | AJ22: =Input!A716 -> 0 | AL22: 780 | AM22: =Input!A780 -> 0 | AO22: 844 | AP22: =Input!A844 -> 0 | AR22: 908 | AS22: =Input!A908 -> 0 | AU22: 972 | AV22: =Input!A972 -> 0 | AX22: 1036 | AY22: =Input!A1036 -> 0
B23: 13 | C23: =Input!A13 -> 0 | E23: 77 | F23: =Input!A77 -> 0 | H23: 141 | I23: =Input!A141 -> 0 | K23: 205 | L23: =Input!A205 -> 0 | N23: 269 | O23: =Input!A269 -> 0 | Q23: 333 | R23: =Input!A333 -> 0 | T23: 397 | U23: =Input!A397 -> 0 | W23: 461 | X23: =Input!A461 -> 0 | Z23: 525 | AA23: =Input!A525 -> 0 | AC23: 589 | AD23: =Input!A589 -> 0 | AF23: 653 | AG23: =Input!A653 -> 0 | AI23: 717 | AJ23: =Input!A717 -> 0 | AL23: 781 | AM23: =Input!A781 -> 0 | AO23: 845 | AP23: =Input!A845 -> 0 | AR23: 909 | AS23: =Input!A909 -> 0 | AU23: 973 | AV23: =Input!A973 -> 0 | AX23: 1037 | AY23: =Input!A1037 -> 0
B24: 14 | C24: =Input!A14 -> 0 | E24: 78 | F24: =Input!A78 -> 0 | H24: 142 | I24: =Input!A142 -> 0 | K24: 206 | L24: =Input!A206 -> 0 | N24: 270 | O24: =Input!A270 -> 0 | Q24: 334 | R24: =Input!A334 -> 0 | T24: 398 | U24: =Input!A398 -> 0 | W24: 462 | X24: =Input!A462 -> 0 | Z24: 526 | AA24: =Input!A526 -> 0 | AC24: 590 | AD24: =Input!A590 -> 0 | AF24: 654 | AG24: =Input!A654 -> 0 | AI24: 718 | AJ24: =Input!A718 -> 0 | AL24: 782 | AM24: =Input!A782 -> 0 | AO24: 846 | AP24: =Input!A846 -> 0 | AR24: 910 | AS24: =Input!A910 -> 0 | AU24: 974 | AV24: =Input!A974 -> 0 | AX24: 1038 | AY24: =Input!A1038 -> 0
B25: 15 | C25: =Input!A15 -> 0 | E25: 79 | F25: =Input!A79 -> 0 | H25: 143 | I25: =Input!A143 -> 0 | K25: 207 | L25: =Input!A207 -> 0 | N25: 271 | O25: =Input!A271 -> 0 | Q25: 335 | R25: =Input!A335 -> 0 | T25: 399 | U25: =Input!A399 -> 0 | W25: 463 | X25: =Input!A463 -> 0 | Z25: 527 | AA25: =Input!A527 -> 0 | AC25: 591 | AD25: =Input!A591 -> 0 | AF25: 655 | AG25: =Input!A655 -> 0 | AI25: 719 | AJ25: =Input!A719 -> 0 | AL25: 783 | AM25: =Input!A783 -> 0 | AO25: 847 | AP25: =Input!A847 -> 0 | AR25: 911 | AS25: =Input!A911 -> 0 | AU25: 975 | AV25: =Input!A975 -> 0 | AX25: 1039 | AY25: =Input!A1039 -> 0
B26: 16 | C26: =Input!A16 -> 0 | E26: 80 | F26: =Input!A80 -> 0 | H26: 144 | I26: =Input!A144 -> 0 | K26: 208 | L26: =Input!A208 -> 0 | N26: 272 | O26: =Input!A272 -> 0 | Q26: 336 | R26: =Input!A336 -> 0 | T26: 400 | U26: =Input!A400 -> 0 | W26: 464 | X26: =Input!A464 -> 0 | Z26: 528 | AA26: =Input!A528 -> 0 | AC26: 592 | AD26: =Input!A592 -> 0 | AF26: 656 | AG26: =Input!A656 -> 0 | AI26: 720 | AJ26: =Input!A720 -> 0 | AL26: 784 | AM26: =Input!A784 -> 0 | AO26: 848 | AP26: =Input!A848 -> 0 | AR26: 912 | AS26: =Input!A912 -> 0 | AU26: 976 | AV26: =Input!A976 -> 0 | AX26: 1040 | AY26: =Input!A1040 -> 0
A27: 3 | B27: 17 | C27: =Input!A17 -> 0 | D27: 11 | E27: 81 | F27: =Input!A81 -> 0 | G27: 19 | H27: 145 | I27: =Input!A145 -> 0 | J27: 27 | K27: 209 | L27: =Input!A209 -> 0 | M27: 35 | N27: 273 | O27: =Input!A273 -> 0 | P27: 43 | Q27: 337 | R27: =Input!A337 -> 0 | S27: 51 | T27: 401 | U27: =Input!A401 -> 0 | V27: 59 | W27: 465 | X27: =Input!A465 -> 0 | Y27: 67 | Z27: 529 | AA27: =Input!A529 -> 0 | AB27: 75 | AC27: 593 | AD27: =Input!A593 -> 0 | AE27: 83 | AF27: 657 | AG27: =Input!A657 -> 0 | AH27: 91 | AI27: 721 | AJ27: =Input!A721 -> 0 | AK27: 99 | AL27: 785 | AM27: =Input!A785 -> 0 | AN27: 107 | AO27: 849 | AP27: =Input!A849 -> 0 | AQ27: 115 | AR27: 913 | AS27: =Input!A913 -> 0 | AT27: 123 | AU27: 977 | AV27: =Input!A977 -> 0 | AW27: 131 | AX27: 1041 | AY27: =Input!A1041 -> 0
B28: 18 | C28: =Input!A18 -> 0 | E28: 82 | F28: =Input!A82 -> 0 | H28: 146 | I28: =Input!A146 -> 0 | K28: 210 | L28: =Input!A210 -> 0 | N28: 274 | O28: =Input!A274 -> 0 | Q28: 338 | R28: =Input!A338 -> 0 | T28: 402 | U28: =Input!A402 -> 0 | W28: 466 | X28: =Input!A466 -> 0 | Z28: 530 | AA28: =Input!A530 -> 0 | AC28: 594 | AD28: =Input!A594 -> 0 | AF28: 658 | AG28: =Input!A658 -> 0 | AI28: 722 | AJ28: =Input!A722 -> 0 | AL28: 786 | AM28: =Input!A786 -> 0 | AO28: 850 | AP28: =Input!A850 -> 0 | AR28: 914 | AS28: =Input!A914 -> 0 | AU28: 978 | AV28: =Input!A978 -> 0 | AX28: 1042 | AY28: =Input!A1042 -> 0
B29: 19 | C29: =Input!A19 -> 0 | E29: 83 | F29: =Input!A83 -> 0 | H29: 147 | I29: =Input!A147 -> 0 | K29: 211 | L29: =Input!A211 -> 0 | N29: 275 | O29: =Input!A275 -> 0 | Q29: 339 | R29: =Input!A339 -> 0 | T29: 403 | U29: =Input!A403 -> 0 | W29: 467 | X29: =Input!A467 -> 0 | Z29: 531 | AA29: =Input!A531 -> 0 | AC29: 595 | AD29: =Input!A595 -> 0 | AF29: 659 | AG29: =Input!A659 -> 0 | AI29: 723 | AJ29: =Input!A723 -> 0 | AL29: 787 | AM29: =Input!A787 -> 0 | AO29: 851 | AP29: =Input!A851 -> 0 | AR29: 915 | AS29: =Input!A915 -> 0 | AU29: 979 | AV29: =Input!A979 -> 0 | AX29: 1043 | AY29: =Input!A1043 -> 0
B30: 20 | C30: =Input!A20 -> 0 | E30: 84 | F30: =Input!A84 -> 0 | H30: 148 | I30: =Input!A148 -> 0 | K30: 212 | L30: =Input!A212 -> 0 | N30: 276 | O30: =Input!A276 -> 0 | Q30: 340 | R30: =Input!A340 -> 0 | T30: 404 | U30: =Input!A404 -> 0 | W30: 468 | X30: =Input!A468 -> 0 | Z30: 532 | AA30: =Input!A532 -> 0 | AC30: 596 | AD30: =Input!A596 -> 0 | AF30: 660 | AG30: =Input!A660 -> 0 | AI30: 724 | AJ30: =Input!A724 -> 0 | AL30: 788 | AM30: =Input!A788 -> 0 | AO30: 852 | AP30: =Input!A852 -> 0 | AR30: 916 | AS30: =Input!A916 -> 0 | AU30: 980 | AV30: =Input!A980 -> 0 | AX30: 1044 | AY30: =Input!A1044 -> 0
B31: 21 | C31: =Input!A21 -> 0 | E31: 85 | F31: =Input!A85 -> 0 | H31: 149 | I31: =Input!A149 -> 0 | K31: 213 | L31: =Input!A213 -> 0 | N31: 277 | O31: =Input!A277 -> 0 | Q31: 341 | R31: =Input!A341 -> 0 | T31: 405 | U31: =Input!A405 -> 0 | W31: 469 | X31: =Input!A469 -> 0 | Z31: 533 | AA31: =Input!A533 -> 0 | AC31: 597 | AD31: =Input!A597 -> 0 | AF31: 661 | AG31: =Input!A661 -> 0 | AI31: 725 | AJ31: =Input!A725 -> 0 | AL31: 789 | AM31: =Input!A789 -> 0 | AO31: 853 | AP31: =Input!A853 -> 0 | AR31: 917 | AS31: =Input!A917 -> 0 | AU31: 981 | AV31: =Input!A981 -> 0 | AX31: 1045 | AY31: =Input!A1045 -> 0
B32: 22 | C32: =Input!A22 -> 0 | E32: 86 | F32: =Input!A86 -> 0 | H32: 150 | I32: =Input!A150 -> 0 | K32: 214 | L32: =Input!A214 -> 0 | N32: 278 | O32: =Input!A278 -> 0 | Q32: 342 | R32: =Input!A342 -> 0 | T32: 406 | U32: =Input!A406 -> 0 | W32: 470 | X32: =Input!A470 -> 0 | Z32: 534 | AA32: =Input!A534 -> 0 | AC32: 598 | AD32: =Input!A598 -> 0 | AF32: 662 | AG32: =Input!A662 -> 0 | AI32: 726 | AJ32: =Input!A726 -> 0 | AL32: 790 | AM32: =Input!A790 -> 0 | AO32: 854 | AP32: =Input!A854 -> 0 | AR32: 918 | AS32: =Input!A918 -> 0 | AU32: 982 | AV32: =Input!A982 -> 0 | AX32: 1046 | AY32: =Input!A1046 -> 0
B33: 23 | C33: =Input!A23 -> 0 | E33: 87 | F33: =Input!A87 -> 0 | H33: 151 | I33: =Input!A151 -> 0 | K33: 215 | L33: =Input!A215 -> 0 | N33: 279 | O33: =Input!A279 -> 0 | Q33: 343 | R33: =Input!A343 -> 0 | T33: 407 | U33: =Input!A407 -> 0 | W33: 471 | X33: =Input!A471 -> 0 | Z33: 535 | AA33: =Input!A535 -> 0 | AC33: 599 | AD33: =Input!A599 -> 0 | AF33: 663 | AG33: =Input!A663 -> 0 | AI33: 727 | AJ33: =Input!A727 -> 0 | AL33: 791 | AM33: =Input!A791 -> 0 | AO33: 855 | AP33: =Input!A855 -> 0 | AR33: 919 | AS33: =Input!A919 -> 0 | AU33: 983 | AV33: =Input!A983 -> 0 | AX33: 1047 | AY33: =Input!A1047 -> 0
B34: 24 | C34: =Input!A24 -> 0 | E34: 88 | F34: =Input!A88 -> 0 | H34: 152 | I34: =Input!A152 -> 0 | K34: 216 | L34: =Input!A216 -> 0 | N34: 280 | O34: =Input!A280 -> 0 | Q34: 344 | R34: =Input!A344 -> 0 | T34: 408 | U34: =Input!A408 -> 0 | W34: 472 | X34: =Input!A472 -> 0 | Z34: 536 | AA34: =Input!A536 -> 0 | AC34: 600 | AD34: =Input!A600 -> 0 | AF34: 664 | AG34: =Input!A664 -> 0 | AI34: 728 | AJ34: =Input!A728 -> 0 | AL34: 792 | AM34: =Input!A792 -> 0 | AO34: 856 | AP34: =Input!A856 -> 0 | AR34: 920 | AS34: =Input!A920 -> 0 | AU34: 984 | AV34: =Input!A984 -> 0 | AX34: 1048 | AY34: =Input!A1048 -> 0
A35: 4 | B35: 25 | C35: =Input!A25 -> 0 | D35: 12 | E35: 89 | F35: =Input!A89 -> 0 | G35: 20 | H35: 153 | I35: =Input!A153 -> 0 | J35: 28 | K35: 217 | L35: =Input!A217 -> 0 | M35: 36 | N35: 281 | O35: =Input!A281 -> 0 | P35: 44 | Q35: 345 | R35: =Input!A345 -> 0 | S35: 52 | T35: 409 | U35: =Input!A409 -> 0 | V35: 60 | W35: 473 | X35: =Input!A473 -> 0 | Y35: 68 | Z35: 537 | AA35: =Input!A537 -> 0 | AB35: 76 | AC35: 601 | AD35: =Input!A601 -> 0 | AE35: 84 | AF35: 665 | AG35: =Input!A665 -> 0 | AH35: 92 | AI35: 729 | AJ35: =Input!A729 -> 0 | AK35: 100 | AL35: 793 | AM35: =Input!A793 -> 0 | AN35: 108 | AO35: 857 | AP35: =Input!A857 -> 0 | AQ35: 116 | AR35: 921 | AS35: =Input!A921 -> 0 | AT35: 124 | AU35: 985 | AV35: =Input!A985 -> 0 | AW35: 132 | AX35: 1049 | AY35: =Input!A1049 -> 0
B36: 26 | C36: =Input!A26 -> 0 | E36: 90 | F36: =Input!A90 -> 0 | H36: 154 | I36: =Input!A154 -> 0 | K36: 218 | L36: =Input!A218 -> 0 | N36: 282 | O36: =Input!A282 -> 0 | Q36: 346 | R36: =Input!A346 -> 0 | T36: 410 | U36: =Input!A410 -> 0 | W36: 474 | X36: =Input!A474 -> 0 | Z36: 538 | AA36: =Input!A538 -> 0 | AC36: 602 | AD36: =Input!A602 -> 0 | AF36: 666 | AG36: =Input!A666 -> 0 | AI36: 730 | AJ36: =Input!A730 -> 0 | AL36: 794 | AM36: =Input!A794 -> 0 | AO36: 858 | AP36: =Input!A858 -> 0 | AR36: 922 | AS36: =Input!A922 -> 0 | AU36: 986 | AV36: =Input!A986 -> 0 | AX36: 1050 | AY36: =Input!A1050 -> 0
B37: 27 | C37: =Input!A27 -> 0 | E37: 91 | F37: =Input!A91 -> 0 | H37: 155 | I37: =Input!A155 -> 0 | K37: 219 | L37: =Input!A219 -> 0 | N37: 283 | O37: =Input!A283 -> 0 | Q37: 347 | R37: =Input!A347 -> 0 | T37: 411 | U37: =Input!A411 -> 0 | W37: 475 | X37: =Input!A475 -> 0 | Z37: 539 | AA37: =Input!A539 -> 0 | AC37: 603 | AD37: =Input!A603 -> 0 | AF37: 667 | AG37: =Input!A667 -> 0 | AI37: 731 | AJ37: =Input!A731 -> 0 | AL37: 795 | AM37: =Input!A795 -> 0 | AO37: 859 | AP37: =Input!A859 -> 0 | AR37: 923 | AS37: =Input!A923 -> 0 | AU37: 987 | AV37: =Input!A987 -> 0 | AX37: 1051 | AY37: =Input!A1051 -> 0
B38: 28 | C38: =Input!A28 -> 0 | E38: 92 | F38: =Input!A92 -> 0 | H38: 156 | I38: =Input!A156 -> 0 | K38: 220 | L38: =Input!A220 -> 0 | N38: 284 | O38: =Input!A284 -> 0 | Q38: 348 | R38: =Input!A348 -> 0 | T38: 412 | U38: =Input!A412 -> 0 | W38: 476 | X38: =Input!A476 -> 0 | Z38: 540 | AA38: =Input!A540 -> 0 | AC38: 604 | AD38: =Input!A604 -> 0 | AF38: 668 | AG38: =Input!A668 -> 0 | AI38: 732 | AJ38: =Input!A732 -> 0 | AL38: 796 | AM38: =Input!A796 -> 0 | AO38: 860 | AP38: =Input!A860 -> 0 | AR38: 924 | AS38: =Input!A924 -> 0 | AU38: 988 | AV38: =Input!A988 -> 0 | AX38: 1052 | AY38: =Input!A1052 -> 0
B39: 29 | C39: =Input!A29 -> 0 | E39: 93 | F39: =Input!A93 -> 0 | H39: 157 | I39: =Input!A157 -> 0 | K39: 221 | L39: =Input!A221 -> 0 | N39: 285 | O39: =Input!A285 -> 0 | Q39: 349 | R39: =Input!A349 -> 0 | T39: 413 | U39: =Input!A413 -> 0 | W39: 477 | X39: =Input!A477 -> 0 | Z39: 541 | AA39: =Input!A541 -> 0 | AC39: 605 | AD39: =Input!A605 -> 0 | AF39: 669 | AG39: =Input!A669 -> 0 | AI39: 733 | AJ39: =Input!A733 -> 0 | AL39: 797 | AM39: =Input!A797 -> 0 | AO39: 861 | AP39: =Input!A861 -> 0 | AR39: 925 | AS39: =Input!A925 -> 0 | AU39: 989 | AV39: =Input!A989 -> 0 | AX39: 1053 | AY39: =Input!A1053 -> 0
B40: 30 | C40: =Input!A30 -> 0 | E40: 94 | F40: =Input!A94 -> 0 | H40: 158 | I40: =Input!A158 -> 0 | K40: 222 | L40: =Input!A222 -> 0 | N40: 286 | O40: =Input!A286 -> 0 | Q40: 350 | R40: =Input!A350 -> 0 | T40: 414 | U40: =Input!A414 -> 0 | W40: 478 | X40: =Input!A478 -> 0 | Z40: 542 | AA40: =Input!A542 -> 0 | AC40: 606 | AD40: =Input!A606 -> 0 | AF40: 670 | AG40: =Input!A670 -> 0 | AI40: 734 | AJ40: =Input!A734 -> 0 | AL40: 798 | AM40: =Input!A798 -> 0 | AO40: 862 | AP40: =Input!A862 -> 0 | AR40: 926 | AS40: =Input!A926 -> 0 | AU40: 990 | AV40: =Input!A990 -> 0 | AX40: 1054 | AY40: =Input!A1054 -> 0
B41: 31 | C41: =Input!A31 -> 0 | E41: 95 | F41: =Input!A95 -> 0 | H41: 159 | I41: =Input!A159 -> 0 | K41: 223 | L41: =Input!A223 -> 0 | N41: 287 | O41: =Input!A287 -> 0 | Q41: 351 | R41: =Input!A351 -> 0 | T41: 415 | U41: =Input!A415 -> 0 | W41: 479 | X41: =Input!A479 -> 0 | Z41: 543 | AA41: =Input!A543 -> 0 | AC41: 607 | AD41: =Input!A607 -> 0 | AF41: 671 | AG41: =Input!A671 -> 0 | AI41: 735 | AJ41: =Input!A735 -> 0 | AL41: 799 | AM41: =Input!A799 -> 0 | AO41: 863 | AP41: =Input!A863 -> 0 | AR41: 927 | AS41: =Input!A927 -> 0 | AU41: 991 | AV41: =Input!A991 -> 0 | AX41: 1055 | AY41: =Input!A1055 -> 0
B42: 32 | C42: =Input!A32 -> 0 | E42: 96 | F42: =Input!A96 -> 0 | H42: 160 | I42: =Input!A160 -> 0 | K42: 224 | L42: =Input!A224 -> 0 | N42: 288 | O42: =Input!A288 -> 0 | Q42: 352 | R42: =Input!A352 -> 0 | T42: 416 | U42: =Input!A416 -> 0 | W42: 480 | X42: =Input!A480 -> 0 | Z42: 544 | AA42: =Input!A544 -> 0 | AC42: 608 | AD42: =Input!A608 -> 0 | AF42: 672 | AG42: =Input!A672 -> 0 | AI42: 736 | AJ42: =Input!A736 -> 0 | AL42: 800 | AM42: =Input!A800 -> 0 | AO42: 864 | AP42: =Input!A864 -> 0 | AR42: 928 | AS42: =Input!A928 -> 0 | AU42: 992 | AV42: =Input!A992 -> 0 | AX42: 1056 | AY42: =Input!A1056 -> 0
...
